[06/Sep/2020 07:25:57] "GET / HTTP/1.1" 200 16351
[06/Sep/2020 07:25:58] "GET /static/admin/css/fonts.css HTTP/1.1" 200 423
[06/Sep/2020 07:25:58] "GET /static/admin/fonts/Roboto-Regular-webfont.woff HTTP/1.1" 200 85876
[06/Sep/2020 07:25:58] "GET /static/admin/fonts/Roboto-Bold-webfont.woff HTTP/1.1" 200 86184
[06/Sep/2020 07:25:58] "GET /static/admin/fonts/Roboto-Light-webfont.woff HTTP/1.1" 200 85692
Not Found: /favicon.ico
[06/Sep/2020 07:25:59] "GET /favicon.ico HTTP/1.1" 404 1975
/home/ubuntu/Project/ENet/ENet/settings.py changed, reloading.
Performing system checks...

System check identified no issues (0 silenced).

You have 18 unapplied migration(s). Your project may not work properly until you apply the migrations for app(s): admin, auth, contenttypes, sessions.
Run 'python manage.py migrate' to apply them.
September 06, 2020 - 07:25:53
Django version 3.0.3, using settings 'ENet.settings'
Starting development server at http://0.0.0.0:8001/
Quit the server with CONTROL-C.
Watching for file changes with StatReloader
/home/ubuntu/Project/ENet/ENet/urls.py changed, reloading.
Performing system checks...

System check identified no issues (0 silenced).

You have 18 unapplied migration(s). Your project may not work properly until you apply the migrations for app(s): admin, auth, contenttypes, sessions.
Run 'python manage.py migrate' to apply them.
September 06, 2020 - 07:36:57
Django version 3.0.3, using settings 'ENet.settings'
Starting development server at http://0.0.0.0:8001/
Quit the server with CONTROL-C.
Watching for file changes with StatReloader
Exception in thread django-main-thread:
Traceback (most recent call last):
  File "/home/ubuntu/anaconda3/lib/python3.8/threading.py", line 932, in _bootstrap_inner
    self.run()
  File "/home/ubuntu/anaconda3/lib/python3.8/threading.py", line 870, in run
    self._target(*self._args, **self._kwargs)
  File "/home/ubuntu/anaconda3/lib/python3.8/site-packages/django/utils/autoreload.py", line 53, in wrapper
    fn(*args, **kwargs)
  File "/home/ubuntu/anaconda3/lib/python3.8/site-packages/django/core/management/commands/runserver.py", line 117, in inner_run
    self.check(display_num_errors=True)
  File "/home/ubuntu/anaconda3/lib/python3.8/site-packages/django/core/management/base.py", line 392, in check
    all_issues = self._run_checks(
  File "/home/ubuntu/anaconda3/lib/python3.8/site-packages/django/core/management/base.py", line 382, in _run_checks
    return checks.run_checks(**kwargs)
  File "/home/ubuntu/anaconda3/lib/python3.8/site-packages/django/core/checks/registry.py", line 72, in run_checks
    new_errors = check(app_configs=app_configs)
  File "/home/ubuntu/anaconda3/lib/python3.8/site-packages/django/core/checks/urls.py", line 13, in check_url_config
    return check_resolver(resolver)
  File "/home/ubuntu/anaconda3/lib/python3.8/site-packages/django/core/checks/urls.py", line 23, in check_resolver
    return check_method()
  File "/home/ubuntu/anaconda3/lib/python3.8/site-packages/django/urls/resolvers.py", line 407, in check
    for pattern in self.url_patterns:
  File "/home/ubuntu/anaconda3/lib/python3.8/site-packages/django/utils/functional.py", line 48, in __get__
    res = instance.__dict__[self.name] = self.func(instance)
  File "/home/ubuntu/anaconda3/lib/python3.8/site-packages/django/urls/resolvers.py", line 588, in url_patterns
    patterns = getattr(self.urlconf_module, "urlpatterns", self.urlconf_module)
  File "/home/ubuntu/anaconda3/lib/python3.8/site-packages/django/utils/functional.py", line 48, in __get__
    res = instance.__dict__[self.name] = self.func(instance)
  File "/home/ubuntu/anaconda3/lib/python3.8/site-packages/django/urls/resolvers.py", line 581, in urlconf_module
    return import_module(self.urlconf_name)
  File "/home/ubuntu/anaconda3/lib/python3.8/importlib/__init__.py", line 127, in import_module
    return _bootstrap._gcd_import(name[level:], package, level)
  File "<frozen importlib._bootstrap>", line 1014, in _gcd_import
  File "<frozen importlib._bootstrap>", line 991, in _find_and_load
  File "<frozen importlib._bootstrap>", line 975, in _find_and_load_unlocked
  File "<frozen importlib._bootstrap>", line 671, in _load_unlocked
  File "<frozen importlib._bootstrap_external>", line 783, in exec_module
  File "<frozen importlib._bootstrap>", line 219, in _call_with_frames_removed
  File "/home/ubuntu/Project/ENet/ENet/urls.py", line 21, in <module>
    url(r'^ENet$', views.KNet),
NameError: name 'url' is not defined
/home/ubuntu/Project/ENet/ENet/urls.py changed, reloading.
Performing system checks...

Watching for file changes with StatReloader
Exception in thread django-main-thread:
Traceback (most recent call last):
  File "/home/ubuntu/anaconda3/lib/python3.8/threading.py", line 932, in _bootstrap_inner
    self.run()
  File "/home/ubuntu/anaconda3/lib/python3.8/threading.py", line 870, in run
    self._target(*self._args, **self._kwargs)
  File "/home/ubuntu/anaconda3/lib/python3.8/site-packages/django/utils/autoreload.py", line 53, in wrapper
    fn(*args, **kwargs)
  File "/home/ubuntu/anaconda3/lib/python3.8/site-packages/django/core/management/commands/runserver.py", line 117, in inner_run
    self.check(display_num_errors=True)
  File "/home/ubuntu/anaconda3/lib/python3.8/site-packages/django/core/management/base.py", line 392, in check
    all_issues = self._run_checks(
  File "/home/ubuntu/anaconda3/lib/python3.8/site-packages/django/core/management/base.py", line 382, in _run_checks
    return checks.run_checks(**kwargs)
  File "/home/ubuntu/anaconda3/lib/python3.8/site-packages/django/core/checks/registry.py", line 72, in run_checks
    new_errors = check(app_configs=app_configs)
  File "/home/ubuntu/anaconda3/lib/python3.8/site-packages/django/core/checks/urls.py", line 13, in check_url_config
    return check_resolver(resolver)
  File "/home/ubuntu/anaconda3/lib/python3.8/site-packages/django/core/checks/urls.py", line 23, in check_resolver
    return check_method()
  File "/home/ubuntu/anaconda3/lib/python3.8/site-packages/django/urls/resolvers.py", line 407, in check
    for pattern in self.url_patterns:
  File "/home/ubuntu/anaconda3/lib/python3.8/site-packages/django/utils/functional.py", line 48, in __get__
    res = instance.__dict__[self.name] = self.func(instance)
  File "/home/ubuntu/anaconda3/lib/python3.8/site-packages/django/urls/resolvers.py", line 588, in url_patterns
    patterns = getattr(self.urlconf_module, "urlpatterns", self.urlconf_module)
  File "/home/ubuntu/anaconda3/lib/python3.8/site-packages/django/utils/functional.py", line 48, in __get__
    res = instance.__dict__[self.name] = self.func(instance)
  File "/home/ubuntu/anaconda3/lib/python3.8/site-packages/django/urls/resolvers.py", line 581, in urlconf_module
    return import_module(self.urlconf_name)
  File "/home/ubuntu/anaconda3/lib/python3.8/importlib/__init__.py", line 127, in import_module
    return _bootstrap._gcd_import(name[level:], package, level)
  File "<frozen importlib._bootstrap>", line 1014, in _gcd_import
  File "<frozen importlib._bootstrap>", line 991, in _find_and_load
  File "<frozen importlib._bootstrap>", line 975, in _find_and_load_unlocked
  File "<frozen importlib._bootstrap>", line 671, in _load_unlocked
  File "<frozen importlib._bootstrap_external>", line 783, in exec_module
  File "<frozen importlib._bootstrap>", line 219, in _call_with_frames_removed
  File "/home/ubuntu/Project/ENet/ENet/urls.py", line 21, in <module>
    url(r'^ENet$', views.ENet),
NameError: name 'url' is not defined
/home/ubuntu/Project/ENet/ENet/urls.py changed, reloading.
Performing system checks...

Watching for file changes with StatReloader
Exception in thread django-main-thread:
Traceback (most recent call last):
  File "/home/ubuntu/anaconda3/lib/python3.8/threading.py", line 932, in _bootstrap_inner
    self.run()
  File "/home/ubuntu/anaconda3/lib/python3.8/threading.py", line 870, in run
    self._target(*self._args, **self._kwargs)
  File "/home/ubuntu/anaconda3/lib/python3.8/site-packages/django/utils/autoreload.py", line 53, in wrapper
    fn(*args, **kwargs)
  File "/home/ubuntu/anaconda3/lib/python3.8/site-packages/django/core/management/commands/runserver.py", line 117, in inner_run
    self.check(display_num_errors=True)
  File "/home/ubuntu/anaconda3/lib/python3.8/site-packages/django/core/management/base.py", line 392, in check
    all_issues = self._run_checks(
  File "/home/ubuntu/anaconda3/lib/python3.8/site-packages/django/core/management/base.py", line 382, in _run_checks
    return checks.run_checks(**kwargs)
  File "/home/ubuntu/anaconda3/lib/python3.8/site-packages/django/core/checks/registry.py", line 72, in run_checks
    new_errors = check(app_configs=app_configs)
  File "/home/ubuntu/anaconda3/lib/python3.8/site-packages/django/core/checks/urls.py", line 13, in check_url_config
    return check_resolver(resolver)
  File "/home/ubuntu/anaconda3/lib/python3.8/site-packages/django/core/checks/urls.py", line 23, in check_resolver
    return check_method()
  File "/home/ubuntu/anaconda3/lib/python3.8/site-packages/django/urls/resolvers.py", line 407, in check
    for pattern in self.url_patterns:
  File "/home/ubuntu/anaconda3/lib/python3.8/site-packages/django/utils/functional.py", line 48, in __get__
    res = instance.__dict__[self.name] = self.func(instance)
  File "/home/ubuntu/anaconda3/lib/python3.8/site-packages/django/urls/resolvers.py", line 588, in url_patterns
    patterns = getattr(self.urlconf_module, "urlpatterns", self.urlconf_module)
  File "/home/ubuntu/anaconda3/lib/python3.8/site-packages/django/utils/functional.py", line 48, in __get__
    res = instance.__dict__[self.name] = self.func(instance)
  File "/home/ubuntu/anaconda3/lib/python3.8/site-packages/django/urls/resolvers.py", line 581, in urlconf_module
    return import_module(self.urlconf_name)
  File "/home/ubuntu/anaconda3/lib/python3.8/importlib/__init__.py", line 127, in import_module
    return _bootstrap._gcd_import(name[level:], package, level)
  File "<frozen importlib._bootstrap>", line 1014, in _gcd_import
  File "<frozen importlib._bootstrap>", line 991, in _find_and_load
  File "<frozen importlib._bootstrap>", line 975, in _find_and_load_unlocked
  File "<frozen importlib._bootstrap>", line 671, in _load_unlocked
  File "<frozen importlib._bootstrap_external>", line 783, in exec_module
  File "<frozen importlib._bootstrap>", line 219, in _call_with_frames_removed
  File "/home/ubuntu/Project/ENet/ENet/urls.py", line 18, in <module>
    from . import views
ImportError: cannot import name 'views' from 'ENet' (/home/ubuntu/Project/ENet/ENet/__init__.py)
  File "manage.py", line 16
    ) from exc
         ^
SyntaxError: invalid syntax
Watching for file changes with StatReloader
Exception in thread django-main-thread:
Traceback (most recent call last):
  File "/home/ubuntu/anaconda3/lib/python3.8/threading.py", line 932, in _bootstrap_inner
    self.run()
  File "/home/ubuntu/anaconda3/lib/python3.8/threading.py", line 870, in run
    self._target(*self._args, **self._kwargs)
  File "/home/ubuntu/anaconda3/lib/python3.8/site-packages/django/utils/autoreload.py", line 53, in wrapper
    fn(*args, **kwargs)
  File "/home/ubuntu/anaconda3/lib/python3.8/site-packages/django/core/management/commands/runserver.py", line 117, in inner_run
    self.check(display_num_errors=True)
  File "/home/ubuntu/anaconda3/lib/python3.8/site-packages/django/core/management/base.py", line 392, in check
    all_issues = self._run_checks(
  File "/home/ubuntu/anaconda3/lib/python3.8/site-packages/django/core/management/base.py", line 382, in _run_checks
    return checks.run_checks(**kwargs)
  File "/home/ubuntu/anaconda3/lib/python3.8/site-packages/django/core/checks/registry.py", line 72, in run_checks
    new_errors = check(app_configs=app_configs)
  File "/home/ubuntu/anaconda3/lib/python3.8/site-packages/django/core/checks/urls.py", line 13, in check_url_config
    return check_resolver(resolver)
  File "/home/ubuntu/anaconda3/lib/python3.8/site-packages/django/core/checks/urls.py", line 23, in check_resolver
    return check_method()
  File "/home/ubuntu/anaconda3/lib/python3.8/site-packages/django/urls/resolvers.py", line 407, in check
    for pattern in self.url_patterns:
  File "/home/ubuntu/anaconda3/lib/python3.8/site-packages/django/utils/functional.py", line 48, in __get__
    res = instance.__dict__[self.name] = self.func(instance)
  File "/home/ubuntu/anaconda3/lib/python3.8/site-packages/django/urls/resolvers.py", line 588, in url_patterns
    patterns = getattr(self.urlconf_module, "urlpatterns", self.urlconf_module)
  File "/home/ubuntu/anaconda3/lib/python3.8/site-packages/django/utils/functional.py", line 48, in __get__
    res = instance.__dict__[self.name] = self.func(instance)
  File "/home/ubuntu/anaconda3/lib/python3.8/site-packages/django/urls/resolvers.py", line 581, in urlconf_module
    return import_module(self.urlconf_name)
  File "/home/ubuntu/anaconda3/lib/python3.8/importlib/__init__.py", line 127, in import_module
    return _bootstrap._gcd_import(name[level:], package, level)
  File "<frozen importlib._bootstrap>", line 1014, in _gcd_import
  File "<frozen importlib._bootstrap>", line 991, in _find_and_load
  File "<frozen importlib._bootstrap>", line 975, in _find_and_load_unlocked
  File "<frozen importlib._bootstrap>", line 671, in _load_unlocked
  File "<frozen importlib._bootstrap_external>", line 783, in exec_module
  File "<frozen importlib._bootstrap>", line 219, in _call_with_frames_removed
  File "/home/ubuntu/Project/ENet/ENet/urls.py", line 22, in <module>
    url(r'^ENet$', views.ENet),
NameError: name 'url' is not defined
/home/ubuntu/Project/ENet/ENet/urls.py changed, reloading.
Performing system checks...

/home/ubuntu/Project/ENet/ENet/urls.py changed, reloading.
Performing system checks...

Watching for file changes with StatReloader
Watching for file changes with StatReloader
/home/ubuntu/Project/ENet/ENet/urls.py changed, reloading.
Performing system checks...

System check identified no issues (0 silenced).

You have 18 unapplied migration(s). Your project may not work properly until you apply the migrations for app(s): admin, auth, contenttypes, sessions.
Run 'python manage.py migrate' to apply them.
September 06, 2020 - 07:43:57
Django version 3.0.3, using settings 'ENet.settings'
Starting development server at http://0.0.0.0:8001/
Quit the server with CONTROL-C.
Watching for file changes with StatReloader
Not Found: /
[06/Sep/2020 07:44:22] "GET / HTTP/1.1" 404 1924
Not Found: /favicon.ico
[06/Sep/2020 07:44:22] "GET /favicon.ico HTTP/1.1" 404 1975
[06/Sep/2020 07:44:29] "GET /ENet HTTP/1.1" 200 6079
Not Found: /load
[06/Sep/2020 07:44:29] "POST /load HTTP/1.1" 404 1955
Not Found: /
[06/Sep/2020 07:44:48] "GET / HTTP/1.1" 404 1924
/home/ubuntu/Project/ENet/ENet/views.py changed, reloading.
Performing system checks...

System check identified no issues (0 silenced).

You have 18 unapplied migration(s). Your project may not work properly until you apply the migrations for app(s): admin, auth, contenttypes, sessions.
Run 'python manage.py migrate' to apply them.
September 06, 2020 - 07:44:02
Django version 3.0.3, using settings 'ENet.settings'
Starting development server at http://0.0.0.0:8001/
Quit the server with CONTROL-C.
Watching for file changes with StatReloader
